<?xml version="1.0" ?>
<!-- =================================================================================== -->
<!-- |    This document was autogenerated by xacro from /home/gizmo/gizmo_ws/ros/catkin_ws/src/cram_v1/cram_description/robots/cram_v1_rig.urdf.xacro | -->
<!-- |    EDITING THIS FILE BY HAND IS NOT RECOMMENDED                                 | -->
<!-- =================================================================================== -->
<!-- Based on version 0.4.1 of the franka panda xacro from github.com/frankaemika/franka_ros/franka_description and
 widowx xacro from https://github.com/RobotnikAutomation/widowx_arm -->
<robot name="widowx_arm">
    <!--   <transmission name="tran1">-->
    <!--    <type>transmission_interface/SimpleTransmission</type>-->
    <!--    <joint name="widowx_joint_1"/>-->
    <!--    <actuator name="motor1">-->
    <!--      <hardwareInterface>hardware_interface/PositionJointInterface</hardwareInterface>-->
    <!--      <mechanicalReduction>1</mechanicalReduction>-->
    <!--    </actuator>-->
    <!--  </transmission>-->
    <!--   <transmission name="tran2">-->
    <!--    <type>transmission_interface/SimpleTransmission</type>-->
    <!--    <joint name="widowx_joint_2"/>-->
    <!--    <actuator name="motor2">-->
    <!--      <hardwareInterface>hardware_interface/PositionJointInterface</hardwareInterface>-->
    <!--      <mechanicalReduction>1</mechanicalReduction>-->
    <!--    </actuator>-->
    <!--  </transmission>-->
    <!--   <transmission name="tran3">-->
    <!--    <type>transmission_interface/SimpleTransmission</type>-->
    <!--    <joint name="widowx_joint_3"/>-->
    <!--    <actuator name="motor3">-->
    <!--      <hardwareInterface>hardware_interface/PositionJointInterface</hardwareInterface>-->
    <!--      <mechanicalReduction>1</mechanicalReduction>-->
    <!--    </actuator>-->
    <!--  </transmission>-->
    <!--   <transmission name="tran4">-->
    <!--    <type>transmission_interface/SimpleTransmission</type>-->
    <!--    <joint name="widowx_joint_4"/>-->
    <!--    <actuator name="motor4">-->
    <!--      <hardwareInterface>hardware_interface/PositionJointInterface</hardwareInterface>-->
    <!--      <mechanicalReduction>1</mechanicalReduction>-->
    <!--    </actuator>-->
    <!--  </transmission>-->
    <!--   <transmission name="tran1">-->
    <!--    <type>transmission_interface/SimpleTransmission</type>-->
    <!--    <joint name="widowx_joint_1"/>-->
    <!--    <actuator name="motor1">-->
    <!--      <hardwareInterface>hardware_interface/PositionJointInterface</hardwareInterface>-->
    <!--      <mechanicalReduction>1</mechanicalReduction>-->
    <!--    </actuator>-->
    <!--  </transmission>-->
    <!--   <transmission name="tran2">-->
    <!--    <type>transmission_interface/SimpleTransmission</type>-->
    <!--    <joint name="widowx_joint_2"/>-->
    <!--    <actuator name="motor2">-->
    <!--      <hardwareInterface>hardware_interface/PositionJointInterface</hardwareInterface>-->
    <!--      <mechanicalReduction>1</mechanicalReduction>-->
    <!--    </actuator>-->
    <!--  </transmission>-->
    <!--   <transmission name="tran3">-->
    <!--    <type>transmission_interface/SimpleTransmission</type>-->
    <!--    <joint name="widowx_joint_3"/>-->
    <!--    <actuator name="motor3">-->
    <!--      <hardwareInterface>hardware_interface/PositionJointInterface</hardwareInterface>-->
    <!--      <mechanicalReduction>1</mechanicalReduction>-->
    <!--    </actuator>-->
    <!--  </transmission>-->
    <!--   <transmission name="tran4">-->
    <!--    <type>transmission_interface/SimpleTransmission</type>-->
    <!--    <joint name="widowx_joint_4"/>-->
    <!--    <actuator name="motor4">-->
    <!--      <hardwareInterface>hardware_interface/PositionJointInterface</hardwareInterface>-->
    <!--      <mechanicalReduction>1</mechanicalReduction>-->
    <!--    </actuator>-->
    <!--  </transmission>-->
    <!-- Base for the 2 robot arms -->
    <link name="base">
        <visual>
            <origin rpy="0 0 0" xyz="0 0 0.02" />
            <geometry>
                <box size="0.935 0.31 0.04" />
            </geometry>
            <material name="White">
                <color rgba="1.0 1.0 1.0 1.0" />
            </material>
        </visual>
        <collision>
            <origin rpy="0 0 0" xyz="0 0 0.02" />
            <geometry>
                <box size="0.935 0.31 0.04" />
            </geometry>
        </collision>
        <inertial>
            <mass value="0.1" />
            <origin xyz="0 0 0" rpy="0 0 0" />
            <inertia ixx="0.03" iyy="0.03" izz="0.03" ixy="0.0" ixz="0.0" iyz="0.0" />
        </inertial>
    </link>
    <link name="buildplate">
        <visual>
            <origin rpy="0 0 0" xyz="0.15 0.15 0" />
            <geometry>
                <box size="0.3 0.3 0.004" />
            </geometry>
            <material name="Blue">
                <color rgba="0.0 0.0 1.0 1.0" />
            </material>
        </visual>
        <collision>
            <origin rpy="0 0 0" xyz="0.15 0.15 0" />
            <geometry>
                <box size="0.3 0.3 0.004" />
            </geometry>
        </collision>
        <inertial>
            <mass value="0.1" />
            <origin xyz="0 0 0" rpy="0 0 0" />
            <inertia ixx="0.03" iyy="0.03" izz="0.03" ixy="0.0" ixz="0.0" iyz="0.0" />
        </inertial>
    </link>
    <joint name="buildplate_joint" type="fixed">
        <origin rpy="0 0 0" xyz="-0.15 -0.15 0.04" />
        <parent link="base" />
        <child link="buildplate" />
    </joint>
    <joint name="widowx_1_joint_base" type="fixed">
        <parent link="base" />
        <child link="widowx_1_arm_base_link" />
        <origin rpy=" 0 0 0 " xyz="-0.245 0  0.04" />
    </joint>
    <!-- links -->
    <link name="widowx_1_arm_base_link">
        <visual>
            <origin rpy="0 0 0" xyz="0 0 0" />
            <geometry>
                <mesh filename="package://cram_description/meshes/widowx/base_link.stl" />
            </geometry>
            <material name="">
                <color rgba="0.15 0.15 0.15 1.0" />
            </material>
        </visual>
        <collision>
            <origin rpy="0 0 0" xyz="0 0 0" />
            <geometry>
                <mesh filename="package://cram_description/meshes/widowx/base_link.stl" />
            </geometry>
        </collision>
        <inertial>
            <origin rpy="0 0 0" xyz="0 0 0" />
            <mass value="1" />
            <inertia ixx="1.0" ixy="0.0" ixz="0.0" iyy="1.0" iyz="0.0" izz="1.0" />
        </inertial>
    </link>
    <link name="widowx_1_shoulder_link">
        <visual>
            <origin rpy="0 0 0" xyz="0 0 0" />
            <geometry>
                <mesh filename="package://cram_description/meshes/widowx/shoulder_link.stl" />
            </geometry>
            <material name="">
                <color rgba="0.15 0.15 0.15 1.0" />
            </material>
        </visual>
        <collision>
            <origin rpy="0 0 0" xyz="0 0 0" />
            <geometry>
                <mesh filename="package://cram_description/meshes/widowx/shoulder_link.stl" />
            </geometry>
        </collision>
        <inertial>
            <origin rpy="0 0 0" xyz="0 0 0" />
            <mass value="1" />
            <inertia ixx="1.0" ixy="0.0" ixz="0.0" iyy="1.0" iyz="0.0" izz="1.0" />
        </inertial>
    </link>
    <link name="widowx_1_biceps_link">
        <visual>
            <origin rpy="0 0 0" xyz="0.04825 0 0.14" />
            <!--origin xyz="0 0 0" rpy="0 0 0" /-->
            <geometry>
                <mesh filename="package://cram_description/meshes/widowx/biceps_link.stl" />
            </geometry>
            <material name="">
                <color rgba="0.15 0.15 0.15 1.0" />
            </material>
        </visual>
        <collision>
            <origin rpy="0 0 0" xyz="0.04825 0 0.14" />
            <geometry>
                <mesh filename="package://cram_description/meshes/widowx/biceps_link.stl" />
            </geometry>
        </collision>
        <inertial>
            <origin rpy="0 0 0" xyz="0 0 0" />
            <mass value="1" />
            <inertia ixx="1.0" ixy="0.0" ixz="0.0" iyy="1.0" iyz="0.0" izz="1.0" />
        </inertial>
    </link>
    <link name="widowx_1_forearm_link">
        <visual>
            <origin rpy="0 0 0" xyz="0 0 0.14203000000000002" />
            <!--origin xyz="0 0 0" rpy="0 0 0" /-->
            <geometry>
                <mesh filename="package://cram_description/meshes/widowx/forearm_link.stl" />
            </geometry>
            <material name="">
                <color rgba="0.15 0.15 0.15 1.0" />
            </material>
        </visual>
        <collision>
            <origin rpy="0 0 0" xyz="0 0 0.14203000000000002" />
            <geometry>
                <mesh filename="package://cram_description/meshes/widowx/forearm_link.stl" />
            </geometry>
        </collision>
        <inertial>
            <origin rpy="0 0 0" xyz="0 0 0" />
            <mass value="1" />
            <inertia ixx="1.0" ixy="0.0" ixz="0.0" iyy="1.0" iyz="0.0" izz="1.0" />
        </inertial>
    </link>
    <link name="widowx_1_wrist_1_link">
        <visual>
            <origin rpy="0 0 -3.141" xyz="0 0 0" />
            --&gt;
            <geometry>
                <mesh filename="package://cram_description/meshes/widowx/wrist_1_link.stl" />
            </geometry>
            <material name="">
                <color rgba="0.15 0.15 0.15 1.0" />
            </material>
        </visual>
        <collision>
            <origin rpy="0 0 -3.141" xyz="0 0 0" />
            <geometry>
                <mesh filename="package://cram_description/meshes/widowx/wrist_1_link.stl" />
            </geometry>
        </collision>
        <inertial>
            <origin rpy="0 0 0" xyz="0 0 0" />
            <mass value="1" />
            <inertia ixx="1.0" ixy="0.0" ixz="0.0" iyy="1.0" iyz="0.0" izz="1.0" />
        </inertial>
    </link>
    <!-- joints -->
    <joint name="widowx_1_joint_1" type="revolute">
        <origin rpy="0 0 0" xyz="0 0 0.125" />
        <parent link="widowx_1_arm_base_link" />
        <child link="widowx_1_shoulder_link" />
        <axis xyz="0 0 1" />
        <limit effort="0" lower="-2.617" upper="2.617" velocity="7.016" />
    </joint>
    <joint name="widowx_1_joint_2" type="revolute">
        <!--origin xyz="0.04825 0 0.14203" rpy="0 0 0" /-->
        <origin rpy="0 0 0" xyz="0 0 0" />
        <parent link="widowx_1_shoulder_link" />
        <child link="widowx_1_biceps_link" />
        <axis xyz="0 1 0" />
        <limit effort="0" lower="-1.60" upper="1.60" velocity="5.760" />
    </joint>
    <joint name="widowx_1_joint_3" type="revolute">
        <origin rpy="0 1.570795 0" xyz="0.04825 0 0.14203000000000002" />
        <parent link="widowx_1_biceps_link" />
        <child link="widowx_1_forearm_link" />
        <axis xyz="0 1 0" />
        <limit effort="0" lower="-1.571" upper="1.571" velocity="5.760" />
    </joint>
    <joint name="widowx_1_joint_4" type="revolute">
        <origin rpy="0 0 0" xyz="0 0 0.14203000000000002" />
        <parent link="widowx_1_forearm_link" />
        <child link="widowx_1_wrist_1_link" />
        <axis xyz="0 1 0" />
        <limit effort="0" lower="-1.60" upper="1.60" velocity="8.168" />
    </joint>
    <joint name="widowx_1_hotend_joint" type="revolute">
        <!--        <origin xyz="0 0 ${M_SCALE*71.5}" rpy="0 0 0" />-->
        <parent link="widowx_1_wrist_1_link" />
        <child link="widowx_1_hotend" />
        <axis xyz="0 0 1" />
        <limit effort="0" lower="-2.617" upper="2.617" velocity="1.571" />
        <origin rpy="0 0 -0.7853975" xyz="0 0 0.0365" />
    </joint>
    <link name="widowx_1_hotend">
        <visual>
            <origin rpy="0 0 -0.7853975" xyz="0 0 0.0365" />
            <geometry>
                <mesh filename="package://cram_description/meshes/hotend/dragon_hotend.stl" scale="0.001 0.001 0.001" />
            </geometry>
            <material name="">
                <color rgba="0.75 0.12 0.06 1.0" />
            </material>
        </visual>
        <collision>
            <origin rpy="0 0 -0.7853975" xyz="0 0 0.0365" />
            <geometry>
                <mesh filename="package://cram_description/meshes/hotend/dragon_hotend.stl" scale="0.001 0.001 0.001" />
            </geometry>
        </collision>
        <inertial>
            <origin rpy="0 0 0" xyz="0 0 0" />
            <mass value="1" />
            <inertia ixx="1.0" ixy="0.0" ixz="0.0" iyy="1.0" iyz="0.0" izz="1.0" />
        </inertial>
    </link>
    <joint name="widowx_2_joint_base" type="fixed">
        <parent link="base" />
        <child link="widowx_2_arm_base_link" />
        <origin rpy="0 0 3.14159" xyz="0.245 0 0.04" />
    </joint>
    <!-- links -->
    <link name="widowx_2_arm_base_link">
        <visual>
            <origin rpy="0 0 0" xyz="0 0 0" />
            <geometry>
                <mesh filename="package://cram_description/meshes/widowxl/base_link.stl" />
            </geometry>
            <material name="">
                <color rgba="0.15 0.15 0.15 1.0" />
            </material>
        </visual>
        <collision>
            <origin rpy="0 0 0" xyz="0 0 0" />
            <geometry>
                <mesh filename="package://cram_description/meshes/widowxl/base_link.stl" />
            </geometry>
        </collision>
        <inertial>
            <origin rpy="0 0 0" xyz="0 0 0" />
            <mass value="1" />
            <inertia ixx="1.0" ixy="0.0" ixz="0.0" iyy="1.0" iyz="0.0" izz="1.0" />
        </inertial>
    </link>
    <link name="widowx_2_shoulder_link">
        <visual>
            <origin rpy="0 0 0" xyz="0 0 0" />
            <geometry>
                <mesh filename="package://cram_description/meshes/widowxl/shoulder_link.stl" />
            </geometry>
            <material name="">
                <color rgba="0.15 0.15 0.15 1.0" />
            </material>
        </visual>
        <collision>
            <origin rpy="0 0 0" xyz="0 0 0" />
            <geometry>
                <mesh filename="package://cram_description/meshes/widowxl/shoulder_link.stl" />
            </geometry>
        </collision>
        <inertial>
            <origin rpy="0 0 0" xyz="0 0 0" />
            <mass value="1" />
            <inertia ixx="1.0" ixy="0.0" ixz="0.0" iyy="1.0" iyz="0.0" izz="1.0" />
        </inertial>
    </link>
    <link name="widowx_2_biceps_link">
        <visual>
            <origin rpy="0 0 0" xyz="0.04825 0 0.14" />
            <!--origin xyz="0 0 0" rpy="0 0 0" /-->
            <geometry>
                <mesh filename="package://cram_description/meshes/widowxl/biceps_link.stl" />
            </geometry>
            <material name="">
                <color rgba="0.15 0.15 0.15 1.0" />
            </material>
        </visual>
        <collision>
            <origin rpy="0 0 0" xyz="0.04825 0 0.14" />
            <geometry>
                <mesh filename="package://cram_description/meshes/widowxl/biceps_link.stl" />
            </geometry>
        </collision>
        <inertial>
            <origin rpy="0 0 0" xyz="0 0 0" />
            <mass value="1" />
            <inertia ixx="1.0" ixy="0.0" ixz="0.0" iyy="1.0" iyz="0.0" izz="1.0" />
        </inertial>
    </link>
    <link name="widowx_2_forearm_link">
        <visual>
            <origin rpy="0 0 0" xyz="0 0 0.14203000000000002" />
            <!--origin xyz="0 0 0" rpy="0 0 0" /-->
            <geometry>
                <mesh filename="package://cram_description/meshes/widowxl/forearm_link.stl" />
            </geometry>
            <material name="">
                <color rgba="0.15 0.15 0.15 1.0" />
            </material>
        </visual>
        <collision>
            <origin rpy="0 0 0" xyz="0 0 0.14203000000000002" />
            <geometry>
                <mesh filename="package://cram_description/meshes/widowxl/forearm_link.stl" />
            </geometry>
        </collision>
        <inertial>
            <origin rpy="0 0 0" xyz="0 0 0" />
            <mass value="1" />
            <inertia ixx="1.0" ixy="0.0" ixz="0.0" iyy="1.0" iyz="0.0" izz="1.0" />
        </inertial>
    </link>
    <link name="widowx_2_wrist_1_link">
        <visual>
            <origin rpy="0 0 -3.141" xyz="0 0 0" />
            --&gt;
            <geometry>
                <mesh filename="package://cram_description/meshes/widowx/wrist_1_link.stl" />
            </geometry>
            <material name="">
                <color rgba="0.15 0.15 0.15 1.0" />
            </material>
        </visual>
        <collision>
            <origin rpy="0 0 -3.141" xyz="0 0 0" />
            <geometry>
                <mesh filename="package://cram_description/meshes/widowx/wrist_1_link.stl" />
            </geometry>
        </collision>
        <inertial>
            <origin rpy="0 0 0" xyz="0 0 0" />
            <mass value="1" />
            <inertia ixx="1.0" ixy="0.0" ixz="0.0" iyy="1.0" iyz="0.0" izz="1.0" />
        </inertial>
    </link>
    <!-- joints -->
    <joint name="widowx_2_joint_1" type="revolute">
        <origin rpy="0 0 0" xyz="0 0 0.125" />
        <parent link="widowx_2_arm_base_link" />
        <child link="widowx_2_shoulder_link" />
        <axis xyz="0 0 1" />
        <limit effort="0" lower="-2.617" upper="2.617" velocity="7.016" />
    </joint>
    <joint name="widowx_2_joint_2" type="revolute">
        <!--origin xyz="0.04825 0 0.14203" rpy="0 0 0" /-->
        <origin rpy="0 0 0" xyz="0 0 0" />
        <parent link="widowx_2_shoulder_link" />
        <child link="widowx_2_biceps_link" />
        <axis xyz="0 1 0" />
        <limit effort="0" lower="-1.571" upper="1.571" velocity="5.760" />
    </joint>
    <joint name="widowx_2_joint_3" type="revolute">
        <origin rpy="0 1.570795 0" xyz="0.04825 0 0.14203000000000002" />
        <parent link="widowx_2_biceps_link" />
        <child link="widowx_2_forearm_link" />
        <axis xyz="0 1 0" />
        <limit effort="0" lower="-1.571" upper="1.571" velocity="5.760" />
    </joint>
    <joint name="widowx_2_joint_4" type="revolute">
        <origin rpy="0 0 0" xyz="0 0 0.14203000000000002" />
        <parent link="widowx_2_forearm_link" />
        <child link="widowx_2_wrist_1_link" />
        <axis xyz="0 1 0" />
        <limit effort="0" lower="-1.60" upper="1.60" velocity="8.168" />
    </joint>
    <joint name="widowx_2_hotend_joint" type="revolute">
        <!--        <origin xyz="0 0 ${M_SCALE*71.5}" rpy="0 0 0" />-->
        <parent link="widowx_2_wrist_1_link" />
        <child link="widowx_2_hotend" />
        <axis xyz="0 0 1" />
        <limit effort="0" lower="-2.617" upper="2.617" velocity="1.571" />
        <origin rpy="0 0 -0.7853975" xyz="0 0 0.0365" />
    </joint>
    <link name="widowx_2_hotend">
        <visual>
            <origin rpy="0 0 -0.7853975" xyz="0 0 0.0365" />
            <geometry>
                <mesh filename="package://cram_description/meshes/hotend/dragon_hotend.stl" scale="0.001 0.001 0.001" />
            </geometry>
            <material name="">
                <color rgba="0.75 0.12 0.06 1.0" />
            </material>
        </visual>
        <collision>
            <origin rpy="0 0 -0.7853975" xyz="0 0 0.0365" />
            <geometry>
                <mesh filename="package://cram_description/meshes/hotend/dragon_hotend.stl" scale="0.001 0.001 0.001" />
            </geometry>
        </collision>
        <inertial>
            <origin rpy="0 0 0" xyz="0 0 0" />
            <mass value="1" />
            <inertia ixx="1.0" ixy="0.0" ixz="0.0" iyy="1.0" iyz="0.0" izz="1.0" />
        </inertial>
    </link>
    <transmission name="trans_widowx_1_joint_1">
        <type>transmission_interface/SimpleTransmission</type>
        <joint name="widowx_1_joint_1">
            <hardwareInterface>hardware_interface/EffortJointInterface</hardwareInterface>
        </joint>
        <actuator name="widowx_1_joint_1_motor">
            <hardwareInterface>hardware_interface/EffortJointInterface</hardwareInterface>
            <mechanicalReduction>1</mechanicalReduction>
        </actuator>
    </transmission>
    <transmission name="trans_widowx_1_joint_2">
        <type>transmission_interface/SimpleTransmission</type>
        <joint name="widowx_1_joint_2">
            <hardwareInterface>hardware_interface/EffortJointInterface</hardwareInterface>
        </joint>
        <actuator name="widowx_1_joint_2_motor">
            <hardwareInterface>hardware_interface/EffortJointInterface</hardwareInterface>
            <mechanicalReduction>1</mechanicalReduction>
        </actuator>
    </transmission>
    <transmission name="trans_widowx_1_joint_3">
        <type>transmission_interface/SimpleTransmission</type>
        <joint name="widowx_1_joint_3">
            <hardwareInterface>hardware_interface/EffortJointInterface</hardwareInterface>
        </joint>
        <actuator name="widowx_1_joint_3_motor">
            <hardwareInterface>hardware_interface/EffortJointInterface</hardwareInterface>
            <mechanicalReduction>1</mechanicalReduction>
        </actuator>
    </transmission>
    <transmission name="trans_widowx_1_joint_4">
        <type>transmission_interface/SimpleTransmission</type>
        <joint name="widowx_1_joint_4">
            <hardwareInterface>hardware_interface/EffortJointInterface</hardwareInterface>
        </joint>
        <actuator name="widowx_1_joint_4_motor">
            <hardwareInterface>hardware_interface/EffortJointInterface</hardwareInterface>
            <mechanicalReduction>1</mechanicalReduction>
        </actuator>
    </transmission>
    <transmission name="trans_widowx_1_hotend_joint">
        <type>transmission_interface/SimpleTransmission</type>
        <joint name="widowx_1_hotend_joint">
            <hardwareInterface>hardware_interface/EffortJointInterface</hardwareInterface>
        </joint>
        <actuator name="widowx_1_hotend_joint_motor">
            <hardwareInterface>hardware_interface/EffortJointInterface</hardwareInterface>
            <mechanicalReduction>1</mechanicalReduction>
        </actuator>
    </transmission>
    <transmission name="trans_widowx_2_joint_1">
        <type>transmission_interface/SimpleTransmission</type>
        <joint name="widowx_2_joint_1">
            <hardwareInterface>hardware_interface/EffortJointInterface</hardwareInterface>
        </joint>
        <actuator name="widowx_2_joint_1_motor">
            <hardwareInterface>hardware_interface/EffortJointInterface</hardwareInterface>
            <mechanicalReduction>1</mechanicalReduction>
        </actuator>
    </transmission>
    <transmission name="trans_widowx_2_joint_2">
        <type>transmission_interface/SimpleTransmission</type>
        <joint name="widowx_2_joint_2">
            <hardwareInterface>hardware_interface/EffortJointInterface</hardwareInterface>
        </joint>
        <actuator name="widowx_2_joint_2_motor">
            <hardwareInterface>hardware_interface/EffortJointInterface</hardwareInterface>
            <mechanicalReduction>1</mechanicalReduction>
        </actuator>
    </transmission>
    <transmission name="trans_widowx_2_joint_3">
        <type>transmission_interface/SimpleTransmission</type>
        <joint name="widowx_2_joint_3">
            <hardwareInterface>hardware_interface/EffortJointInterface</hardwareInterface>
        </joint>
        <actuator name="widowx_2_joint_3_motor">
            <hardwareInterface>hardware_interface/EffortJointInterface</hardwareInterface>
            <mechanicalReduction>1</mechanicalReduction>
        </actuator>
    </transmission>
    <transmission name="trans_widowx_2_joint_4">
        <type>transmission_interface/SimpleTransmission</type>
        <joint name="widowx_2_joint_4">
            <hardwareInterface>hardware_interface/EffortJointInterface</hardwareInterface>
        </joint>
        <actuator name="widowx_2_joint_4_motor">
            <hardwareInterface>hardware_interface/EffortJointInterface</hardwareInterface>
            <mechanicalReduction>1</mechanicalReduction>
        </actuator>
    </transmission>
    <transmission name="trans_widowx_2_hotend_joint">
        <type>transmission_interface/SimpleTransmission</type>
        <joint name="widowx_2_hotend_joint">
            <hardwareInterface>hardware_interface/EffortJointInterface</hardwareInterface>
        </joint>
        <actuator name="widowx_2_hotend_joint_motor">
            <hardwareInterface>hardware_interface/EffortJointInterface</hardwareInterface>
            <mechanicalReduction>1</mechanicalReduction>
        </actuator>
    </transmission>
    <gazebo>
        <plugin name="gazebo_ros_control">
            <robotNamespace>/</robotNamespace>
        </plugin>
    </gazebo>
</robot>

