<?xml version="1.0" ?>
<!-- =================================================================================== -->
<!-- |    This document was autogenerated by xacro from /home/gizmo/gizmo_ws/ros/catkin_ws/src/cram_v1/cram_description/robots/widowx_arm_hotend.urdf.xacro | -->
<!-- |    EDITING THIS FILE BY HAND IS NOT RECOMMENDED                                 | -->
<!-- =================================================================================== -->
<!-- Based on version 0.4.1 of the franka panda xacro from github.com/frankaemika/franka_ros/franka_description and
 widowx xacro from https://github.com/RobotnikAutomation/widowx_arm -->
<robot name="widowx_arm">
    <transmission name="tran1">
        <type>transmission_interface/SimpleTransmission</type>
        <joint name="joint_1" />
        <actuator name="motor1">
            <hardwareInterface>hardware_interface/PositionJointInterface</hardwareInterface>
            <mechanicalReduction>1</mechanicalReduction>
        </actuator>
    </transmission>
    <transmission name="tran2">
        <type>transmission_interface/SimpleTransmission</type>
        <joint name="joint_2" />
        <actuator name="motor2">
            <hardwareInterface>hardware_interface/PositionJointInterface</hardwareInterface>
            <mechanicalReduction>1</mechanicalReduction>
        </actuator>
    </transmission>
    <transmission name="tran3">
        <type>transmission_interface/SimpleTransmission</type>
        <joint name="joint_3" />
        <actuator name="motor3">
            <hardwareInterface>hardware_interface/PositionJointInterface</hardwareInterface>
            <mechanicalReduction>1</mechanicalReduction>
        </actuator>
    </transmission>
    <transmission name="tran4">
        <type>transmission_interface/SimpleTransmission</type>
        <joint name="joint_4" />
        <actuator name="motor4">
            <hardwareInterface>hardware_interface/PositionJointInterface</hardwareInterface>
            <mechanicalReduction>1</mechanicalReduction>
        </actuator>
    </transmission>
    <!-- links -->
    <link name="widowx_arm_base_link">
        <visual>
            <origin rpy="0 0 0" xyz="0 0 0" />
            <geometry>
                <mesh filename="package://cram_description/meshes/widowx/base_link.stl" />
            </geometry>
            <material name="">
                <color rgba="0.15 0.15 0.15 1.0" />
            </material>
        </visual>
        <collision>
            <origin rpy="0 0 0" xyz="0 0 0" />
            <geometry>
                <mesh filename="package://cram_description/meshes/widowx/base_link.stl" />
            </geometry>
        </collision>
        <inertial>
            <origin rpy="0 0 0" xyz="0 0 0" />
            <mass value="1" />
            <inertia ixx="1.0" ixy="0.0" ixz="0.0" iyy="1.0" iyz="0.0" izz="1.0" />
        </inertial>
    </link>
    <link name="widowx_shoulder_link">
        <visual>
            <origin rpy="0 0 0" xyz="0 0 0" />
            <geometry>
                <mesh filename="package://cram_description/meshes/widowx/shoulder_link.stl" />
            </geometry>
            <material name="">
                <color rgba="0.15 0.15 0.15 1.0" />
            </material>
        </visual>
        <collision>
            <origin rpy="0 0 0" xyz="0 0 0" />
            <geometry>
                <mesh filename="package://cram_description/meshes/widowx/shoulder_link.stl" />
            </geometry>
        </collision>
        <inertial>
            <origin rpy="0 0 0" xyz="0 0 0" />
            <mass value="1" />
            <inertia ixx="1.0" ixy="0.0" ixz="0.0" iyy="1.0" iyz="0.0" izz="1.0" />
        </inertial>
    </link>
    <link name="widowx_biceps_link">
        <visual>
            <origin rpy="0 0 0" xyz="0.04825 0 0.14" />
            <!--origin xyz="0 0 0" rpy="0 0 0" /-->
            <geometry>
                <mesh filename="package://cram_description/meshes/widowx/biceps_link.stl" />
            </geometry>
            <material name="">
                <color rgba="0.15 0.15 0.15 1.0" />
            </material>
        </visual>
        <collision>
            <origin rpy="0 0 0" xyz="0.04825 0 0.14" />
            <geometry>
                <mesh filename="package://cram_description/meshes/widowx/biceps_link.stl" />
            </geometry>
        </collision>
        <inertial>
            <origin rpy="0 0 0" xyz="0 0 0" />
            <mass value="1" />
            <inertia ixx="1.0" ixy="0.0" ixz="0.0" iyy="1.0" iyz="0.0" izz="1.0" />
        </inertial>
    </link>
    <link name="widowx_forearm_link">
        <visual>
            <origin rpy="0 0 0" xyz="0 0 0.14203000000000002" />
            <!--origin xyz="0 0 0" rpy="0 0 0" /-->
            <geometry>
                <mesh filename="package://cram_description/meshes/widowx/forearm_link.stl" />
            </geometry>
            <material name="">
                <color rgba="0.15 0.15 0.15 1.0" />
            </material>
        </visual>
        <collision>
            <origin rpy="0 0 0" xyz="0 0 0.14203000000000002" />
            <geometry>
                <mesh filename="package://cram_description/meshes/widowx/forearm_link.stl" />
            </geometry>
        </collision>
        <inertial>
            <origin rpy="0 0 0" xyz="0 0 0" />
            <mass value="1" />
            <inertia ixx="1.0" ixy="0.0" ixz="0.0" iyy="1.0" iyz="0.0" izz="1.0" />
        </inertial>
    </link>
    <link name="widowx_wrist_1_link">
        <visual>
            <origin rpy="-1.5707 0 0" xyz="0 0 0" />
            <geometry>
                <mesh filename="package://cram_description/meshes/widowx/wrist_bracket.stl" scale="0.001 0.001 0.001" />
            </geometry>
            <material name="">
                <color rgba="0.15 0.15 0.15 1.0" />
            </material>
        </visual>
        <collision>
            <origin rpy="-1.5707 0 0" xyz="0 0 0" />
            <geometry>
                <mesh filename="package://cram_description/meshes/widowx/wrist_bracket.stl" scale="0.001 0.001 0.001" />
            </geometry>
        </collision>
        <inertial>
            <origin rpy="0 0 0" xyz="0 0 0" />
            <mass value="1" />
            <inertia ixx="1.0" ixy="0.0" ixz="0.0" iyy="1.0" iyz="0.0" izz="1.0" />
        </inertial>
    </link>
    <!-- joints -->
    <joint name="widowx_joint_1" type="revolute">
        <origin rpy="0 0 0" xyz="0 0 0.125" />
        <parent link="widowx_arm_base_link" />
        <child link="widowx_shoulder_link" />
        <axis xyz="0 0 1" />
        <limit effort="0" lower="-2.617" upper="2.617" velocity="7.016" />
    </joint>
    <joint name="widowx_joint_2" type="revolute">
        <!--origin xyz="0.04825 0 0.14203" rpy="0 0 0" /-->
        <origin rpy="0 0 0" xyz="0 0 0" />
        <parent link="widowx_shoulder_link" />
        <child link="widowx_biceps_link" />
        <axis xyz="0 1 0" />
        <limit effort="0" lower="-1.571" upper="1.571" velocity="5.760" />
    </joint>
    <joint name="widowx_joint_3" type="revolute">
        <origin rpy="0 1.570795 0" xyz="0.04825 0 0.14203000000000002" />
        <parent link="widowx_biceps_link" />
        <child link="widowx_forearm_link" />
        <axis xyz="0 1 0" />
        <limit effort="0" lower="-1.571" upper="1.571" velocity="5.760" />
    </joint>
    <joint name="widowx_joint_4" type="revolute">
        <origin rpy="0 0 0" xyz="0 0 0.14203000000000002" />
        <parent link="widowx_forearm_link" />
        <child link="widowx_wrist_1_link" />
        <axis xyz="0 1 0" />
        <limit effort="0" lower="-1.745" upper="1.745" velocity="8.168" />
    </joint>
    <joint name="widowx_hotend_joint" type="fixed">
        <parent link="widowx_wrist_1_link" />
        <child link="widowx_hotend" />
        <origin rpy="0 0 0" xyz="0 0 0" />
    </joint>
    <link name="widowx_hotend">
        <visual>
            <origin rpy="0 0 -0.7854" xyz="0 0 0.037" />
            <geometry>
                <mesh filename="package://cram_description/meshes/hotend/dragon_hotend.stl" scale="0.001 0.001 0.001" />
            </geometry>
            <material name="">
                <color rgba="0.75 0.12 0.06 1.0" />
            </material>
        </visual>
        <collision>
            <origin rpy="0 0 -0.7854" xyz="0 0 0.037" />
            <geometry>
                <mesh filename="package://cram_description/meshes/hotend/dragon_hotend.stl" scale="0.001 0.001 0.001" />
            </geometry>
        </collision>
        <inertial>
            <origin rpy="0 0 0" xyz="0 0 0" />
            <mass value="1" />
            <inertia ixx="1.0" ixy="0.0" ixz="0.0" iyy="1.0" iyz="0.0" izz="1.0" />
        </inertial>
    </link>
    <transmission name="trans_widowx_joint_1">
        <type>transmission_interface/SimpleTransmission</type>
        <joint name="widowx_joint_1">
            <hardwareInterface>hardware_interface/EffortJointInterface</hardwareInterface>
        </joint>
        <actuator name="widowx_joint_1_motor">
            <hardwareInterface>hardware_interface/EffortJointInterface</hardwareInterface>
            <mechanicalReduction>1</mechanicalReduction>
        </actuator>
    </transmission>
    <transmission name="trans_widowx_joint_2">
        <type>transmission_interface/SimpleTransmission</type>
        <joint name="widowx_joint_2">
            <hardwareInterface>hardware_interface/EffortJointInterface</hardwareInterface>
        </joint>
        <actuator name="widowx_joint_2_motor">
            <hardwareInterface>hardware_interface/EffortJointInterface</hardwareInterface>
            <mechanicalReduction>1</mechanicalReduction>
        </actuator>
    </transmission>
    <transmission name="trans_widowx_joint_3">
        <type>transmission_interface/SimpleTransmission</type>
        <joint name="widowx_joint_3">
            <hardwareInterface>hardware_interface/EffortJointInterface</hardwareInterface>
        </joint>
        <actuator name="widowx_joint_3_motor">
            <hardwareInterface>hardware_interface/EffortJointInterface</hardwareInterface>
            <mechanicalReduction>1</mechanicalReduction>
        </actuator>
    </transmission>
    <transmission name="trans_widowx_joint_4">
        <type>transmission_interface/SimpleTransmission</type>
        <joint name="widowx_joint_4">
            <hardwareInterface>hardware_interface/EffortJointInterface</hardwareInterface>
        </joint>
        <actuator name="widowx_joint_4_motor">
            <hardwareInterface>hardware_interface/EffortJointInterface</hardwareInterface>
            <mechanicalReduction>1</mechanicalReduction>
        </actuator>
    </transmission>
    <gazebo>
        <plugin name="gazebo_ros_control">
            <robotNamespace>/</robotNamespace>
        </plugin>
    </gazebo>
</robot>

