<?xml version="1.0" ?>
<!-- =================================================================================== -->
<!-- |    This document was autogenerated by xacro from /home/gizmo/gizmo_ws/ros/catkin_ws/src/cram_v1/cram_description/robots/widowx_arm.urdf.xacro | -->
<!-- |    EDITING THIS FILE BY HAND IS NOT RECOMMENDED                                 | -->
<!-- =================================================================================== -->
<robot name="widowx_arm">
    <transmission name="tran1">
        <type>transmission_interface/SimpleTransmission</type>
        <joint name="joint_1">
            <hardwareInterface>hardware_interface/EffortJointInterface</hardwareInterface>
        </joint>
        <actuator name="motor1">
            <hardwareInterface>hardware_interface/PositionJointInterface</hardwareInterface>
            <mechanicalReduction>1</mechanicalReduction>
        </actuator>
    </transmission>
    <transmission name="tran2">
        <type>transmission_interface/SimpleTransmission</type>
        <joint name="joint_2">
            <hardwareInterface>hardware_interface/EffortJointInterface</hardwareInterface>
        </joint>
        <actuator name="motor2">
            <hardwareInterface>hardware_interface/PositionJointInterface</hardwareInterface>
            <mechanicalReduction>1</mechanicalReduction>
        </actuator>
    </transmission>
    <transmission name="tran3">
        <type>transmission_interface/SimpleTransmission</type>
        <joint name="joint_3">
            <hardwareInterface>hardware_interface/EffortJointInterface</hardwareInterface>
        </joint>
        <actuator name="motor3">
            <hardwareInterface>hardware_interface/PositionJointInterface</hardwareInterface>
            <mechanicalReduction>1</mechanicalReduction>
        </actuator>
    </transmission>
    <transmission name="tran4">
        <type>transmission_interface/SimpleTransmission</type>
        <joint name="joint_4">
            <hardwareInterface>hardware_interface/EffortJointInterface</hardwareInterface>
        </joint>
        <actuator name="motor4">
            <hardwareInterface>hardware_interface/PositionJointInterface</hardwareInterface>
            <mechanicalReduction>1</mechanicalReduction>
        </actuator>
    </transmission>
    <link name="base_footprint">
        <visual>
            <origin rpy="0 0 0" xyz="0 0 0" />
            <geometry>
                <box size="0.001 0.001 0.001" />
            </geometry>
        </visual>
    </link>
    <!-- links -->
    <link name="arm_base_link">
        <visual>
            <origin rpy="0 0 0" xyz="0 0 0" />
            <geometry>
                <mesh filename="package://cram_description/meshes/base_link.stl" />
            </geometry>
            <material name="">
                <color rgba="0.15 0.15 0.15 1.0" />
            </material>
        </visual>
        <collision>
            <origin rpy="0 0 0" xyz="0 0 0" />
            <geometry>
                <mesh filename="package://cram_description/meshes/base_link.stl" />
            </geometry>
        </collision>
        <inertial>
            <origin rpy="0 0 0" xyz="0 0 0" />
            <mass value="1" />
            <inertia ixx="1.0" ixy="0.0" ixz="0.0" iyy="1.0" iyz="0.0" izz="1.0" />
        </inertial>
    </link>
    <link name="shoulder_link">
        <visual>
            <origin rpy="0 0 0" xyz="0 0 0" />
            <geometry>
                <mesh filename="package://cram_description/meshes/shoulder_link.stl" />
            </geometry>
            <material name="">
                <color rgba="0.15 0.15 0.15 1.0" />
            </material>
        </visual>
        <collision>
            <origin rpy="0 0 0" xyz="0 0 0" />
            <geometry>
                <mesh filename="package://cram_description/meshes/shoulder_link.stl" />
            </geometry>
        </collision>
        <inertial>
            <origin rpy="0 0 0" xyz="0 0 0" />
            <mass value="1" />
            <inertia ixx="1.0" ixy="0.0" ixz="0.0" iyy="1.0" iyz="0.0" izz="1.0" />
        </inertial>
    </link>
    <link name="biceps_link">
        <visual>
            <origin rpy="0 0 0" xyz="0.04825 0 0.14" />
            <!--origin xyz="0 0 0" rpy="0 0 0" /-->
            <geometry>
                <mesh filename="package://cram_description/meshes/biceps_link.stl" />
            </geometry>
            <material name="">
                <color rgba="0.15 0.15 0.15 1.0" />
            </material>
        </visual>
        <collision>
            <origin rpy="0 0 0" xyz="0.04825 0 0.14" />
            <geometry>
                <mesh filename="package://cram_description/meshes/biceps_link.stl" />
            </geometry>
        </collision>
        <inertial>
            <origin rpy="0 0 0" xyz="0 0 0" />
            <mass value="1" />
            <inertia ixx="1.0" ixy="0.0" ixz="0.0" iyy="1.0" iyz="0.0" izz="1.0" />
        </inertial>
    </link>
    <link name="forearm_link">
        <visual>
            <origin rpy="0 0 0" xyz="0 0 0.14203000000000002" />
            <!--origin xyz="0 0 0" rpy="0 0 0" /-->
            <geometry>
                <mesh filename="package://cram_description/meshes/forearm_link.stl" />
            </geometry>
            <material name="">
                <color rgba="0.15 0.15 0.15 1.0" />
            </material>
        </visual>
        <collision>
            <origin rpy="0 0 0" xyz="0 0 0.14203000000000002" />
            <geometry>
                <mesh filename="package://cram_description/meshes/forearm_link.stl" />
            </geometry>
        </collision>
        <inertial>
            <origin rpy="0 0 0" xyz="0 0 0" />
            <mass value="1" />
            <inertia ixx="1.0" ixy="0.0" ixz="0.0" iyy="1.0" iyz="0.0" izz="1.0" />
        </inertial>
    </link>
    <link name="wrist_1_link">
        <visual>
            <origin rpy="-1.5707 0 0" xyz="0 0 0" />
            <geometry>
                <mesh filename="package://cram_description/meshes/wrist_bracket.stl" scale="0.001 0.001 0.001" />
            </geometry>
            <material name="">
                <color rgba="0.15 0.15 0.15 1.0" />
            </material>
        </visual>
        <collision>
            <origin rpy="-1.5707 0 0" xyz="0 0 0" />
            <geometry>
                <mesh filename="package://cram_description/meshes/wrist_bracket.stl" scale="0.001 0.001 0.001" />
            </geometry>
        </collision>
        <inertial>
            <origin rpy="0 0 0" xyz="0 0 0" />
            <mass value="1" />
            <inertia ixx="1.0" ixy="0.0" ixz="0.0" iyy="1.0" iyz="0.0" izz="1.0" />
        </inertial>
    </link>
    <link name="hotend">
        <visual>
            <origin rpy="0 0 0" xyz="0 0 0.037" />
            <geometry>
                <mesh filename="package://cram_description/meshes/dragon_hotend.stl" scale="0.001 0.001 0.001" />
            </geometry>
            <material name="">
                <color rgba="0.34 0.35 0.36 1.0" />
            </material>
        </visual>
        <collision>
            <origin rpy="0 0 0" xyz="0 0 0.037" />
            <geometry>
                <mesh filename="package://cram_description/meshes/dragon_hotend.stl" scale="0.001 0.001 0.001" />
            </geometry>
        </collision>
        <inertial>
            <origin rpy="0 0 0" xyz="0 0 0" />
            <mass value="1" />
            <inertia ixx="1.0" ixy="0.0" ixz="0.0" iyy="1.0" iyz="0.0" izz="1.0" />
        </inertial>
    </link>
    <!-- joints -->
    <joint name="arm_base_joint" type="fixed">
        <insert_block name="origin" />
        <parent link="base_footprint" />
        <child link="arm_base_link" />
    </joint>
    <joint name="joint_1" type="revolute">
        <origin rpy="0 0 0" xyz="0 0 0.125" />
        <parent link="arm_base_link" />
        <child link="shoulder_link" />
        <axis xyz="0 0 1" />
        <limit effort="0" lower="-2.617" upper="2.617" velocity="7.016" />
    </joint>
    <joint name="joint_2" type="revolute">
        <!--origin xyz="0.04825 0 0.14203" rpy="0 0 0" /-->
        <origin rpy="0 0 0" xyz="0 0 0" />
        <parent link="shoulder_link" />
        <child link="biceps_link" />
        <axis xyz="0 1 0" />
        <limit effort="0" lower="-1.571" upper="1.571" velocity="5.760" />
    </joint>
    <joint name="joint_3" type="revolute">
        <origin rpy="0 1.570795 0" xyz="0.04825 0 0.14203000000000002" />
        <parent link="biceps_link" />
        <child link="forearm_link" />
        <axis xyz="0 1 0" />
        <limit effort="0" lower="-1.571" upper="1.571" velocity="5.760" />
    </joint>
    <joint name="joint_4" type="revolute">
        <origin rpy="0 0 0" xyz="0 0 0.14203000000000002" />
        <parent link="forearm_link" />
        <child link="wrist_1_link" />
        <axis xyz="0 1 0" />
        <limit effort="0" lower="-1.745" upper="1.745" velocity="8.168" />
    </joint>
    <joint name="hotend" type="fixed">
        <!--<insert_block name="origin" />-->
        <parent link="wrist_1_link" />
        <child link="hotend" />
    </joint>
    <!--joint name="${prefix}joint_6" type="fixed">
         <origin xyz = "0 0 ${M_SCALE*43}" rpy="0 0 0" />
         <parent link="${prefix}wrist_2_link" />
         <child link="${prefix}gripper_rail_link" />
         <axis xyz="0 0 1" />
         <limit lower="-0.31" upper="0.1" effort="0" velocity="0.5" />
      </joint-->
    <gazebo>
        <plugin name="gazebo_ros_control">
            <robotNamespace>/</robotNamespace>
        </plugin>
    </gazebo>
</robot>

